<?xml version="1.0" ?>
<sdf version="1.8">
  <model name="quadcopter">
    <pose>0 0 0.082 0 0 0</pose>
    
    <!-- Main body -->
    <link name="base_link">
      <inertial>
        <mass>1.5</mass>
        <inertia>
          <ixx>0.0347563</ixx>
          <ixy>0</ixy>
          <ixz>0</ixz>
          <iyy>0.0458929</iyy>
          <iyz>0</iyz>
          <izz>0.0977</izz>
        </inertia>
        <pose>0 0 0 0 0 0</pose>
      </inertial>
      
      <collision name="base_collision">
        <geometry>
          <box>
            <size>0.47 0.47 0.11</size>
          </box>
        </geometry>
      </collision>
      
      <visual name="base_visual">
        <geometry>
          <mesh>
            <uri>model://quadcopter/meshes/quadcopter_base.dae</uri>
            <scale>1 1 1</scale>
          </mesh>
        </geometry>
        <material>
          <ambient>0.2 0.2 0.2 1.0</ambient>
          <diffuse>0.2 0.2 0.2 1.0</diffuse>
          <specular>0.1 0.1 0.1 1.0</specular>
        </material>
      </visual>
      
      <!-- IMU sensor -->
      <sensor name="imu_sensor" type="imu">
        <always_on>1</always_on>
        <update_rate>200</update_rate>
        <imu>
          <angular_velocity>
            <x>
              <noise type="gaussian">
                <mean>0</mean>
                <stddev>0.009</stddev>
                <bias_mean>0.00075</bias_mean>
                <bias_stddev>0.005</bias_stddev>
              </noise>
            </x>
            <y>
              <noise type="gaussian">
                <mean>0</mean>
                <stddev>0.009</stddev>
                <bias_mean>0.00075</bias_mean>
                <bias_stddev>0.005</bias_stddev>
              </noise>
            </y>
            <z>
              <noise type="gaussian">
                <mean>0</mean>
                <stddev>0.009</stddev>
                <bias_mean>0.00075</bias_mean>
                <bias_stddev>0.005</bias_stddev>
              </noise>
            </z>
          </angular_velocity>
          <linear_acceleration>
            <x>
              <noise type="gaussian">
                <mean>0</mean>
                <stddev>0.021</stddev>
                <bias_mean>0.05</bias_mean>
                <bias_stddev>0.0075</bias_stddev>
              </noise>
            </x>
            <y>
              <noise type="gaussian">
                <mean>0</mean>
                <stddev>0.021</stddev>
                <bias_mean>0.05</bias_mean>
                <bias_stddev>0.0075</bias_stddev>
              </noise>
            </y>
            <z>
              <noise type="gaussian">
                <mean>0</mean>
                <stddev>0.021</stddev>
                <bias_mean>0.05</bias_mean>
                <bias_stddev>0.0075</bias_stddev>
              </noise>
            </z>
          </linear_acceleration>
        </imu>
      </sensor>
      
      <!-- GPS sensor -->
      <sensor name="gps_sensor" type="navsat">
        <always_on>1</always_on>
        <update_rate>10</update_rate>
        <navsat>
          <position_sensing>
            <horizontal>
              <noise type="gaussian">
                <mean>0</mean>
                <stddev>1.0</stddev>
              </noise>
            </horizontal>
            <vertical>
              <noise type="gaussian">
                <mean>0</mean>
                <stddev>1.5</stddev>
              </noise>
            </vertical>
          </position_sensing>
          <velocity_sensing>
            <horizontal>
              <noise type="gaussian">
                <mean>0</mean>
                <stddev>0.1</stddev>
              </noise>
            </horizontal>
            <vertical>
              <noise type="gaussian">
                <mean>0</mean>
                <stddev>0.15</stddev>
              </noise>
            </vertical>
          </velocity_sensing>
        </navsat>
      </sensor>
      
      <!-- Barometer sensor -->
      <sensor name="barometer_sensor" type="air_pressure">
        <always_on>1</always_on>
        <update_rate>20</update_rate>
        <air_pressure>
          <reference_altitude>0</reference_altitude>
          <pressure>
            <noise type="gaussian">
              <mean>0</mean>
              <stddev>0.5</stddev>
            </noise>
          </pressure>
        </air_pressure>
      </sensor>
      
      <!-- Magnetometer sensor -->
      <sensor name="magnetometer_sensor" type="magnetometer">
        <always_on>1</always_on>
        <update_rate>20</update_rate>
        <magnetometer>
          <x>
            <noise type="gaussian">
              <mean>0</mean>
              <stddev>0.0001</stddev>
            </noise>
          </x>
          <y>
            <noise type="gaussian">
              <mean>0</mean>
              <stddev>0.0001</stddev>
            </noise>
          </y>
          <z>
            <noise type="gaussian">
              <mean>0</mean>
              <stddev>0.0001</stddev>
            </noise>
          </z>
        </magnetometer>
      </sensor>
      
      <!-- Camera sensor -->
      <sensor name="camera_sensor" type="camera">
        <always_on>1</always_on>
        <update_rate>30</update_rate>
        <camera>
          <horizontal_fov>1.047</horizontal_fov>
          <image>
            <width>1280</width>
            <height>720</height>
            <format>R8G8B8</format>
          </image>
          <clip>
            <near>0.1</near>
            <far>100</far>
          </clip>
          <noise>
            <type>gaussian</type>
            <mean>0</mean>
            <stddev>0.007</stddev>
          </noise>
        </camera>
        <pose>0.2 0 0 0 0.34 0</pose>
      </sensor>
    </link>
    
    <!-- Rotor 1 -->
    <link name="rotor_1">
      <pose>0.174 0.174 0.06 0 0 0</pose>
      <inertial>
        <mass>0.05</mass>
        <inertia>
          <ixx>0.0000913</ixx>
          <ixy>0</ixy>
          <ixz>0</ixz>
          <iyy>0.0000913</iyy>
          <iyz>0</iyz>
          <izz>0.0001803</izz>
        </inertia>
      </inertial>
      <collision name="rotor_1_collision">
        <geometry>
          <cylinder>
            <length>0.01</length>
            <radius>0.128</radius>
          </cylinder>
        </geometry>
      </collision>
      <visual name="rotor_1_visual">
        <geometry>
          <mesh>
            <uri>model://quadcopter/meshes/propeller_ccw.dae</uri>
            <scale>1 1 1</scale>
          </mesh>
        </geometry>
        <material>
          <ambient>0.7 0.7 0.7 1.0</ambient>
          <diffuse>0.7 0.7 0.7 1.0</diffuse>
          <specular>0.1 0.1 0.1 1.0</specular>
        </material>
      </visual>
    </link>
    
    <!-- Rotor 2 -->
    <link name="rotor_2">
      <pose>-0.174 0.174 0.06 0 0 0</pose>
      <inertial>
        <mass>0.05</mass>
        <inertia>
          <ixx>0.0000913</ixx>
          <ixy>0</ixy>
          <ixz>0</ixz>
          <iyy>0.0000913</iyy>
          <iyz>0</iyz>
          <izz>0.0001803</izz>
        </inertia>
      </inertial>
      <collision name="rotor_2_collision">
        <geometry>
          <cylinder>
            <length>0.01</length>
            <radius>0.128</radius>
          </cylinder>
        </geometry>
      </collision>
      <visual name="rotor_2_visual">
        <geometry>
          <mesh>
            <uri>model://quadcopter/meshes/propeller_cw.dae</uri>
            <scale>1 1 1</scale>
          </mesh>
        </geometry>
        <material>
          <ambient>0.7 0.7 0.7 1.0</ambient>
          <diffuse>0.7 0.7 0.7 1.0</diffuse>
          <specular>0.1 0.1 0.1 1.0</specular>
        </material>
      </visual>
    </link>
    
    <!-- Rotor 3 -->
    <link name="rotor_3">
      <pose>-0.174 -0.174 0.06 0 0 0</pose>
      <inertial>
        <mass>0.05</mass>
        <inertia>
          <ixx>0.0000913</ixx>
          <ixy>0</ixy>
          <ixz>0</ixz>
          <iyy>0.0000913</iyy>
          <iyz>0</iyz>
          <izz>0.0001803</izz>
        </inertia>
      </inertial>
      <collision name="rotor_3_collision">
        <geometry>
          <cylinder>
            <length>0.01</length>
            <radius>0.128</radius>
          </cylinder>
        </geometry>
      </collision>
      <visual name="rotor_3_visual">
        <geometry>
          <mesh>
            <uri>model://quadcopter/meshes/propeller_ccw.dae</uri>
            <scale>1 1 1</scale>
          </mesh>
        </geometry>
        <material>
          <ambient>0.7 0.7 0.7 1.0</ambient>
          <diffuse>0.7 0.7 0.7 1.0</diffuse>
          <specular>0.1 0.1 0.1 1.0</specular>
        </material>
      </visual>
    </link>
    
    <!-- Rotor 4 -->
    <link name="rotor_4">
      <pose>0.174 -0.174 0.06 0 0 0</pose>
      <inertial>
        <mass>0.05</mass>
        <inertia>
          <ixx>0.0000913</ixx>
          <ixy>0</ixy>
          <ixz>0</ixz>
          <iyy>0.0000913</iyy>
          <iyz>0</iyz>
          <izz>0.0001803</izz>
        </inertia>
      </inertial>
      <collision name="rotor_4_collision">
        <geometry>
          <cylinder>
            <length>0.01</length>
            <radius>0.128</radius>
          </cylinder>
        </geometry>
      </collision>
      <visual name="rotor_4_visual">
        <geometry>
          <mesh>
            <uri>model://quadcopter/meshes/propeller_cw.dae</uri>
            <scale>1 1 1</scale>
          </mesh>
        </geometry>
        <material>
          <ambient>0.7 0.7 0.7 1.0</ambient>
          <diffuse>0.7 0.7 0.7 1.0</diffuse>
          <specular>0.1 0.1 0.1 1.0</specular>
        </material>
      </visual>
    </link>
    
    <!-- Joint for rotor 1 -->
    <joint name="rotor_1_joint" type="revolute">
      <parent>base_link</parent>
      <child>rotor_1</child>
      <axis>
        <xyz>0 0 1</xyz>
        <limit>
          <lower>-1e+16</lower>
          <upper>1e+16</upper>
        </limit>
        <dynamics>
          <damping>0.002</damping>
        </dynamics>
      </axis>
      <physics>
        <ode>
          <implicit_spring_damper>1</implicit_spring_damper>
        </ode>
      </physics>
    </joint>
    
    <!-- Joint for rotor 2 -->
    <joint name="rotor_2_joint" type="revolute">
      <parent>base_link</parent>
      <child>rotor_2</child>
      <axis>
        <xyz>0 0 1</xyz>
        <limit>
          <lower>-1e+16</lower>
          <upper>1e+16</upper>
        </limit>
        <dynamics>
          <damping>0.002</damping>
        </dynamics>
      </axis>
      <physics>
        <ode>
          <implicit_spring_damper>1</implicit_spring_damper>
        </ode>
      </physics>
    </joint>
    
    <!-- Joint for rotor 3 -->
    <joint name="rotor_3_joint" type="revolute">
      <parent>base_link</parent>
      <child>rotor_3</child>
      <axis>
        <xyz>0 0 1</xyz>
        <limit>
          <lower>-1e+16</lower>
          <upper>1e+16</upper>
        </limit>
        <dynamics>
          <damping>0.002</damping>
        </dynamics>
      </axis>
      <physics>
        <ode>
          <implicit_spring_damper>1</implicit_spring_damper>
        </ode>
      </physics>
    </joint>
    
    <!-- Joint for rotor 4 -->
    <joint name="rotor_4_joint" type="revolute">
      <parent>base_link</parent>
      <child>rotor_4</child>
      <axis>
        <xyz>0 0 1</xyz>
        <limit>
          <lower>-1e+16</lower>
          <upper>1e+16</upper>
        </limit>
        <dynamics>
          <damping>0.002</damping>
        </dynamics>
      </axis>
      <physics>
        <ode>
          <implicit_spring_damper>1</implicit_spring_damper>
        </ode>
      </physics>
    </joint>
    
    <!-- Multicopter velocity controller plugin -->
    <plugin
      filename="ignition-gazebo-multicopter-motor-model-system"
      name="ignition::gazebo::systems::MulticopterMotorModel">
      <robotNamespace>quadcopter</robotNamespace>
      <jointName>rotor_1_joint</jointName>
      <linkName>rotor_1</linkName>
      <turningDirection>ccw</turningDirection>
      <timeConstantUp>0.0125</timeConstantUp>
      <timeConstantDown>0.025</timeConstantDown>
      <maxRotVelocity>1100</maxRotVelocity>
      <motorConstant>8.54858e-06</motorConstant>
      <momentConstant>0.016</momentConstant>
      <commandSubTopic>command/motor_speed</commandSubTopic>
      <motorNumber>0</motorNumber>
      <rotorDragCoefficient>0.000806428</rotorDragCoefficient>
      <rollingMomentCoefficient>1e-06</rollingMomentCoefficient>
      <motorSpeedPubTopic>motor_speed/0</motorSpeedPubTopic>
      <rotorVelocitySlowdownSim>10</rotorVelocitySlowdownSim>
      <motorType>velocity</motorType>
    </plugin>
    
    <plugin
      filename="ignition-gazebo-multicopter-motor-model-system"
      name="ignition::gazebo::systems::MulticopterMotorModel">
      <robotNamespace>quadcopter</robotNamespace>
      <jointName>rotor_2_joint</jointName>
      <linkName>rotor_2</linkName>
      <turningDirection>cw</turningDirection>
      <timeConstantUp>0.0125</timeConstantUp>
      <timeConstantDown>0.025</timeConstantDown>
      <maxRotVelocity>1100</maxRotVelocity>
      <motorConstant>8.54858e-06</motorConstant>
      <momentConstant>0.016</momentConstant>
      <commandSubTopic>command/motor_speed</commandSubTopic>
      <motorNumber>1</motorNumber>
      <rotorDragCoefficient>0.000806428</rotorDragCoefficient>
      <rollingMomentCoefficient>1e-06</rollingMomentCoefficient>
      <motorSpeedPubTopic>motor_speed/1</motorSpeedPubTopic>
      <rotorVelocitySlowdownSim>10</rotorVelocitySlowdownSim>
      <motorType>velocity</motorType>
    </plugin>
    
    <plugin
      filename="ignition-gazebo-multicopter-motor-model-system"
      name="ignition::gazebo::systems::MulticopterMotorModel">
      <robotNamespace>quadcopter</robotNamespace>
      <jointName>rotor_3_joint</jointName>
      <linkName>rotor_3</linkName>
      <turningDirection>ccw</turningDirection>
      <timeConstantUp>0.0125</timeConstantUp>
      <timeConstantDown>0.025</timeConstantDown>
      <maxRotVelocity>1100</maxRotVelocity>
      <motorConstant>8.54858e-06</motorConstant>
      <momentConstant>0.016</momentConstant>
      <commandSubTopic>command/motor_speed</commandSubTopic>
      <motorNumber>2</motorNumber>
      <rotorDragCoefficient>0.000806428</rotorDragCoefficient>
      <rollingMomentCoefficient>1e-06</rollingMomentCoefficient>
      <motorSpeedPubTopic>motor_speed/2</motorSpeedPubTopic>
      <rotorVelocitySlowdownSim>10</rotorVelocitySlowdownSim>
      <motorType>velocity</motorType>
    </plugin>
    
    <plugin
      filename="ignition-gazebo-multicopter-motor-model-system"
      name="ignition::gazebo::systems::MulticopterMotorModel">
      <robotNamespace>quadcopter</robotNamespace>
      <jointName>rotor_4_joint</jointName>
      <linkName>rotor_4</linkName>
      <turningDirection>cw</turningDirection>
      <timeConstantUp>0.0125</timeConstantUp>
      <timeConstantDown>0.025</timeConstantDown>
      <maxRotVelocity>1100</maxRotVelocity>
      <motorConstant>8.54858e-06</motorConstant>
      <momentConstant>0.016</momentConstant>
      <commandSubTopic>command/motor_speed</commandSubTopic>
      <motorNumber>3</motorNumber>
      <rotorDragCoefficient>0.000806428</rotorDragCoefficient>
      <rollingMomentCoefficient>1e-06</rollingMomentCoefficient>
      <motorSpeedPubTopic>motor_speed/3</motorSpeedPubTopic>
      <rotorVelocitySlowdownSim>10</rotorVelocitySlowdownSim>
      <motorType>velocity</motorType>
    </plugin>
    
    <!-- Multicopter control plugin -->
    <plugin
      filename="ignition-gazebo-multicopter-control-system"
      name="ignition::gazebo::systems::MulticopterVelocityControl">
      <robotNamespace>quadcopter</robotNamespace>
      <commandSubTopic>cmd_vel</commandSubTopic>
      <enableSubTopic>enable</enableSubTopic>
      <comLinkName>base_link</comLinkName>
      <velocityGain>2.7 2.7 2.7</velocityGain>
      <attitudeGain>2 2 2</attitudeGain>
      <angularRateGain>0.5 0.5 0.5</angularRateGain>
      <maximumLinearAcceleration>2 2 2</maximumLinearAcceleration>
      <maximumLinearVelocity>5 5 5</maximumLinearVelocity>
      <maximumAngularVelocity>3 3 3</maximumAngularVelocity>
      <linearVelocityNoiseMean>0 0 0</linearVelocityNoiseMean>
      <linearVelocityNoiseStdDev>0.1 0.1 0.1</linearVelocityNoiseStdDev>
      <angularVelocityNoiseMean>0 0 0</angularVelocityNoiseMean>
      <angularVelocityNoiseStdDev>0.05 0.05 0.05</angularVelocityNoiseStdDev>
      <rotorConfiguration>
        <rotor>
          <jointName>rotor_1_joint</jointName>
          <forceConstant>8.54858e-06</forceConstant>
          <momentConstant>0.016</momentConstant>
          <direction>1</direction>
        </rotor>
        <rotor>
          <jointName>rotor_2_joint</jointName>
          <forceConstant>8.54858e-06</forceConstant>
          <momentConstant>0.016</momentConstant>
          <direction>-1</direction>
        </rotor>
        <rotor>
          <jointName>rotor_3_joint</jointName>
          <forceConstant>8.54858e-06</forceConstant>
          <momentConstant>0.016</momentConstant>
          <direction>1</direction>
        </rotor>
        <rotor>
          <jointName>rotor_4_joint</jointName>
          <forceConstant>8.54858e-06</forceConstant>
          <momentConstant>0.016</momentConstant>
          <direction>-1</direction>
        </rotor>
      </rotorConfiguration>
    </plugin>
    
    <!-- Battery plugin -->
    <plugin
      filename="ignition-gazebo-linearbatteryplugin-system"
      name="ignition::gazebo::systems::LinearBatteryPlugin">
      <battery_name>linear_battery</battery_name>
      <voltage>12.694</voltage>
      <open_circuit_voltage_constant_coef>12.694</open_circuit_voltage_constant_coef>
      <open_circuit_voltage_linear_coef>-3.1424</open_circuit_voltage_linear_coef>
      <initial_charge>1.2009</initial_charge>
      <capacity>1.2009</capacity>
      <resistance>0.061523</resistance>
      <smooth_current_tau>1.9499</smooth_current_tau>
      <power_load>6.6</power_load>
      <power_draining_topic>linear_battery_state_draining</power_draining_topic>
      <power_supply_topic>linear_battery_state_supply</power_supply_topic>
      <enable_recharge>true</enable_recharge>
      <charging_time>3.0</charging_time>
    </plugin>
  </model>
</sdf>
